2025-08-08 10:04:52.942 WARNING (SyncWorker_0) [homeassistant.loader] We found a custom integration exo_pool which has not been tested by Home Assistant. This component might cause stability problems, be sure to disable it if you experience issues with Home Assistant
2025-08-08 10:04:54.623 WARNING (MainThread) [asyncio] Executing <Task pending name='Task-1' coro=<setup_and_run_hass() running at /workspaces/ha-core/homeassistant/runner.py:123> wait_for=<_GatheringFuture pending cb=[Task.task_wakeup()] created at /home/vscode/.local/share/uv/python/cpython-3.13.6-linux-x86_64-gnu/lib/python3.13/asyncio/tasks.py:765> cb=[_run_until_complete_cb() at /home/vscode/.local/share/uv/python/cpython-3.13.6-linux-x86_64-gnu/lib/python3.13/asyncio/base_events.py:181] created at /home/vscode/.local/share/uv/python/cpython-3.13.6-linux-x86_64-gnu/lib/python3.13/asyncio/tasks.py:748> took 0.179 seconds
2025-08-08 10:04:54.632 WARNING (MainThread) [aiohttp_fast_zlib] zlib_ng and isal are not available, falling back to zlib, performance will be degraded.
2025-08-08 10:04:54.759 ERROR (MainThread) [homeassistant.components.http] Failed to create HTTP server at port 8123: [Errno 98] error while attempting to bind on address ('::', 8123, 0, 0): [errno 98] address already in use
2025-08-08 10:04:56.221 WARNING (MainThread) [asyncio] Executing <Task pending name='Task-1' coro=<setup_and_run_hass() running at /workspaces/ha-core/homeassistant/runner.py:123> wait_for=<_GatheringFuture pending cb=[Task.task_wakeup()] created at /home/vscode/.local/share/uv/python/cpython-3.13.6-linux-x86_64-gnu/lib/python3.13/asyncio/tasks.py:765> cb=[_run_until_complete_cb() at /home/vscode/.local/share/uv/python/cpython-3.13.6-linux-x86_64-gnu/lib/python3.13/asyncio/base_events.py:181] created at /home/vscode/.local/share/uv/python/cpython-3.13.6-linux-x86_64-gnu/lib/python3.13/asyncio/tasks.py:748> took 0.293 seconds
2025-08-08 10:04:56.608 WARNING (MainThread) [homeassistant.components.go2rtc.server] 10:04:56.605 ERR [api] listen error="listen tcp 127.0.0.1:11984: bind: address already in use"
2025-08-08 10:04:56.608 WARNING (MainThread) [homeassistant.components.go2rtc.server] 10:04:56.605 ERR [rtsp] listen error="listen tcp 127.0.0.1:18554: bind: address already in use"
2025-08-08 10:05:06.558 WARNING (MainThread) [homeassistant.setup] Setup of go2rtc is taking over 10 seconds.
2025-08-08 10:05:26.599 ERROR (MainThread) [homeassistant.components.go2rtc.server] Go2rtc server didn't start correctly
Traceback (most recent call last):
  File "/workspaces/ha-core/homeassistant/components/go2rtc/server.py", line 127, in _start
    await self._startup_complete.wait()
  File "/home/vscode/.local/share/uv/python/cpython-3.13.6-linux-x86_64-gnu/lib/python3.13/asyncio/locks.py", line 213, in wait
    await fut
asyncio.exceptions.CancelledError

The above exception was the direct cause of the following exception:

Traceback (most recent call last):
  File "/workspaces/ha-core/homeassistant/components/go2rtc/server.py", line 126, in _start
    async with asyncio.timeout(_SETUP_TIMEOUT):
               ~~~~~~~~~~~~~~~^^^^^^^^^^^^^^^^
  File "/home/vscode/.local/share/uv/python/cpython-3.13.6-linux-x86_64-gnu/lib/python3.13/asyncio/timeouts.py", line 116, in __aexit__
    raise TimeoutError from exc_val
TimeoutError
2025-08-08 10:05:26.603 WARNING (MainThread) [homeassistant.components.go2rtc.server] 10:04:56.599 INF go2rtc platform=linux/amd64 revision=fa580c5 version=1.9.9
2025-08-08 10:05:26.603 WARNING (MainThread) [homeassistant.components.go2rtc.server] 10:04:56.600 INF config path=/tmp/go2rtc_db4_u9vi.yaml
2025-08-08 10:05:26.603 WARNING (MainThread) [homeassistant.components.go2rtc.server] 10:04:56.605 ERR [api] listen error="listen tcp 127.0.0.1:11984: bind: address already in use"
2025-08-08 10:05:26.603 WARNING (MainThread) [homeassistant.components.go2rtc.server] 10:04:56.605 ERR [rtsp] listen error="listen tcp 127.0.0.1:18554: bind: address already in use"
2025-08-08 10:05:26.603 WARNING (MainThread) [homeassistant.components.go2rtc.server] 10:04:56.607 INF [webrtc] listen addr=:18555/tcp
2025-08-08 10:05:26.608 WARNING (MainThread) [homeassistant.components.go2rtc.server] exit with signal: terminated
2025-08-08 10:05:26.613 WARNING (MainThread) [homeassistant.components.go2rtc] Could not start go2rtc server
Traceback (most recent call last):
  File "/workspaces/ha-core/homeassistant/components/go2rtc/server.py", line 127, in _start
    await self._startup_complete.wait()
  File "/home/vscode/.local/share/uv/python/cpython-3.13.6-linux-x86_64-gnu/lib/python3.13/asyncio/locks.py", line 213, in wait
    await fut
asyncio.exceptions.CancelledError

The above exception was the direct cause of the following exception:

Traceback (most recent call last):
  File "/workspaces/ha-core/homeassistant/components/go2rtc/server.py", line 126, in _start
    async with asyncio.timeout(_SETUP_TIMEOUT):
               ~~~~~~~~~~~~~~~^^^^^^^^^^^^^^^^
  File "/home/vscode/.local/share/uv/python/cpython-3.13.6-linux-x86_64-gnu/lib/python3.13/asyncio/timeouts.py", line 116, in __aexit__
    raise TimeoutError from exc_val
TimeoutError

The above exception was the direct cause of the following exception:

Traceback (most recent call last):
  File "/workspaces/ha-core/homeassistant/components/go2rtc/__init__.py", line 133, in async_setup
    await server.start()
  File "/workspaces/ha-core/homeassistant/components/go2rtc/server.py", line 98, in start
    await self._start()
  File "/workspaces/ha-core/homeassistant/components/go2rtc/server.py", line 133, in _start
    raise Go2RTCServerStartError from err
homeassistant.components.go2rtc.server.Go2RTCServerStartError: Go2rtc server didn't start correctly
2025-08-08 10:05:26.622 ERROR (MainThread) [homeassistant.setup] Setup failed for 'go2rtc': Integration failed to initialize.
2025-08-08 10:05:26.624 ERROR (MainThread) [homeassistant.setup] Unable to set up dependencies of 'default_config'. Setup failed for dependencies: ['go2rtc']
2025-08-08 10:05:26.625 ERROR (MainThread) [homeassistant.setup] Setup failed for 'default_config': Could not setup dependencies: go2rtc
2025-08-08 10:05:27.819 WARNING (MainThread) [asyncio] Executing <Task pending name='Task-1' coro=<setup_and_run_hass() running at /workspaces/ha-core/homeassistant/runner.py:131> wait_for=<Future pending cb=[Task.task_wakeup()] created at /home/vscode/.local/share/uv/python/cpython-3.13.6-linux-x86_64-gnu/lib/python3.13/asyncio/base_events.py:459> cb=[_run_until_complete_cb() at /home/vscode/.local/share/uv/python/cpython-3.13.6-linux-x86_64-gnu/lib/python3.13/asyncio/base_events.py:181] created at /home/vscode/.local/share/uv/python/cpython-3.13.6-linux-x86_64-gnu/lib/python3.13/asyncio/tasks.py:748> took 1.177 seconds
2025-08-08 10:05:28.096 WARNING (MainThread) [asyncio] Executing <Task pending name='Task-83' coro=<gather_with_limited_concurrency.<locals>.sem_task() running at /workspaces/ha-core/homeassistant/util/async_.py:111> wait_for=<Future pending cb=[_chain_future.<locals>._call_check_cancel() at /home/vscode/.local/share/uv/python/cpython-3.13.6-linux-x86_64-gnu/lib/python3.13/asyncio/futures.py:384, Task.task_wakeup()] created at /home/vscode/.local/share/uv/python/cpython-3.13.6-linux-x86_64-gnu/lib/python3.13/asyncio/base_events.py:459> cb=[gather.<locals>._done_callback() at /home/vscode/.local/share/uv/python/cpython-3.13.6-linux-x86_64-gnu/lib/python3.13/asyncio/tasks.py:820] created at /workspaces/ha-core/homeassistant/util/async_.py:44> took 0.271 seconds
2025-08-08 10:05:28.710 WARNING (MainThread) [asyncio] Executing <Task finished name='Task-83' coro=<gather_with_limited_concurrency.<locals>.sem_task() done, defined at /workspaces/ha-core/homeassistant/util/async_.py:109> result={'context': {'source': 'system'}, 'data': {}, 'description': None, 'description_placeholders': None, ...} created at /workspaces/ha-core/homeassistant/util/async_.py:44> took 0.382 seconds
2025-08-08 10:05:29.288 WARNING (MainThread) [asyncio] Executing <Handle _SelectorDatagramTransport._read_ready() created at /home/vscode/.local/share/uv/python/cpython-3.13.6-linux-x86_64-gnu/lib/python3.13/asyncio/selector_events.py:276> took 0.125 seconds
2025-08-08 10:05:29.449 WARNING (MainThread) [asyncio] Executing <Handle _SelectorSocketTransport._read_ready() created at /home/vscode/.local/share/uv/python/cpython-3.13.6-linux-x86_64-gnu/lib/python3.13/asyncio/selector_events.py:276> took 0.125 seconds
